<mujoco>

    <compiler angle="degree"/>

    <asset>
        <texture type="skybox" builtin="gradient" rgb1="1 1 1" rgb2=".6 .8 1" width="256" height="256"/>
    </asset>

    <!-- IMPORTANT LEG PARAMETERS FOR MODELS -->
    <!-- lr0= 0.46, l1=0.025, l2=0.018, l3=0.028, l4=0.015, rp=0.008, d1=0.0218 -->

    <worldbody>
        <light diffuse=".5 .5 .5" pos="0 0 3" dir="0 0 -1"/>    
        <geom type="plane" size="0.1 .1 0.03" rgba=".9 0 0 1"/>
        <body pos="0 0.0055 0.1">
            <geom name="main_box" mass=".040" type="box" size=".0091 .014 .014" rgba="0 .9 0 1"/>
            
            <camera name="body_cam" mode="fixed" pos="0.2 -0.01 0" euler="90 90 0"/>
            <!-- Extension with slider for jumping -->
            <!-- joint name="rail" type="slide" axis="0 0 1"/ -->
            <joint name="rail" type="slide" axis="0 0 1" damping="0.01" frictionloss="0.01" pos="0 -0.03325 0"/>
            <body name ="main_leg" pos="0.0136 -0.0055 -0.0085">

                <joint name="m1" pos="0 0 0" type="hinge" axis="1 0 0" damping="0.01" armature="0.00065" limited="true" range="-180 180" ref="90"/>
                <geom name="leg1" mass="0.001" type="capsule" fromto="0 0 0 0 0.025 0" size="0.0032"/>
                <site name="knee_start" pos="0 0.0068 0" size="0.002" rgba=".1 .1 .8 0.5"/>
                <body name="lower_leg" pos="0 0.025 0">
                    <joint name="knee1" pos="0 0 0" type="hinge" axis="1 0 0" damping="0.01" armature="0.00065" limited="true" range="-90 90" />
                    <geom name="leg2" type="capsule" mass="0.0015" fromto="0 0 0 0 0 -0.028" size="0.002" rgba=".8 .1 .1 1"/>
                    <site name="m2_pickup" pos="0 0 -0.018" size="0.002" rgba=".1 .1 .8 0.5"/>
                    <site name="knee_pickup" pos="0 0 -0.028" size="0.002" rgba=".1 .1 .8 0.5"/>
                    <site name="ankle_start" pos="0 0 -0.010" size="0.002" rgba=".1 .1 .8 0.5"/>
                    <body name="foot" pos="0 0 -0.028">
                        <joint name="ankle" pos="0 0 0" type="hinge" axis="1 0 0" damping="0.01" stiffness="100" armature="0.00065" limited="true" range="-90 70" ref="-73"/>
                        <geom name="foot1" type="capsule" mass="0.001" fromto="0 -0.015 0 0 0.006 0" size="0.001"/>
                        <site name="ankle_pickup" pos="0 0.006 0" size="0.002" rgba=".1 .1 .8 0.5"/>
                        <site name="end_point" pos="0 -0.015 0" size="0.002" rgba=".1 .6 .8 0.5"/>
                    </body>
                </body>
            </body>

            <site name="x1" pos="0.0136 -0.02 0.00" size="0.002" rgba=".1 .1 .8 0.2"/>
            <body name="servo2" pos="0.0136 -0.0055 0.0043">
                <geom name="motor2" type="cylinder" mass="0.002" fromto="-0.003 0 0 0.003 0 0" size="0.008" rgba=".8 .1 .1 1" />
                <joint name="m2" pos="0 0 0" type="hinge" axis="1 0 0" armature="0.00065" damping="0.01" limited="true" range="-180 180"/>
                
                <site name="s1" pos="0.0 0 0.009" size="0.002" rgba=".1 .1 .8 0.5"/>
            </body>
        </body>
    </worldbody>


    <contact>
        <exclude body1="main_leg" body2="servo2"/>
    </contact>

    
    <tendon>
        <spatial name="m2_tendon" limited="true" range="0 0.0587" width="0.001" rgba=".1 .1 .8 0.5">
            <site site="s1"/>
            <geom geom="motor2" sidesite="x1"/>
            <site site="m2_pickup"/>
        </spatial>

        <!-- adjust the stiffness values of these springs -->
        <spatial name="knee_tendon" springlength="0.05" stiffness="600" width="0.001" rgba=".1 .1 .8 0.5">
            <site site="knee_start"/>
            <site site="knee_pickup"/>
        </spatial>

        <!--spatial name="ankle_tendon" springlength="0.013" stiffness="2000" width="0.001" rgba=".1 .1 .8 0.5">
            <site site="ankle_start"/>
            <site site="ankle_pickup"/>
        </spatial-->
    </tendon>

    <sensor>
        <!-- tendonpos name="tendon_length" tendon="m2_tendon"/-->
        <!-- framepos name="leg_endpoint" objtype="site" objname="end_point"/-->
        <jointpos name="m1" joint="m1"/>
        <jointpos name="m2" joint="m2"/>
    </sensor>

    <actuator>
        <position name="m1" gear="1" ctrllimited="true" ctrlrange="-3.00 3.00"  forcelimited="true" forcerange="-0.157 0.157" joint="m1" kp="1000"/>
        <position name="m2" gear="1" ctrllimited="true"  ctrlrange="-3.00 3.00 " forcelimited="true" forcerange="-0.157 0.157" joint="m2" kp="1000"/>
        <!--motor name="m1" gear="100" joint="m1"/>
        <motor name="m2" gear="10" joint="m2"/-->
    </actuator>
</mujoco>