<mujoco>

    <compiler angle="degree"/>

    <asset>
        <texture type="skybox" builtin="gradient" rgb1="1 1 1" rgb2=".6 .8 1" width="256" height="256"/>
    </asset>

    <option gravity="0 0 -9810"/>

    <!-- IMPORTANT LEG PARAMETERS FOR MODELS -->
    <!-- lr0= 0.46, l1=0.025, l2=0.018, l3=0.028, l4=0.015, rp=0.008, d1=0.0218 -->

    <worldbody>
        <light diffuse="0.5 0.5 0.5" pos="0 0 300" dir="0 0 -1"/>    
        <geom type="plane" size="100 100 0.1" rgba=".9 0 0 1"/>
        <camera name="body_cam" mode="fixed" pos="0.2 -0.01 0.05" euler="90 90 0"/>
        <body pos="0 5.5 60">
            <geom name="main_box" mass="40" type="box" size="9.1 14 14" rgba="0 .9 0 1"/>
            
            <!-- Extension with slider for jumping -->
            <joint name="rail" type="slide" axis="0 0 1" pos="0 0 0" damping="0.1" limited="true" range="-20 10"/>
            <joint name="rail2" type="slide" axis="0 1 0" damping=".1" frictionloss="10000" pos="0 0 0"/>
            <body name ="main_leg" pos="13.6 -5.5 -8.5">

                <joint name="m1" pos="0 0 0" type="hinge" axis="1 0 0" range="-180 180" ref="90" damping="50000"/>
                <geom name="leg1" mass="1" type="capsule" fromto="0 0 0 0 25 0" size="3.2"/>
                <site name="knee_start" pos="0 6.8 0" size="2" rgba=".1 .1 .8 0.5"/>
                <body name="lower_leg" pos="0 25 0">
                    <joint name="knee1" pos="0 0 0" type="hinge" axis="1 0 0" limited="true" range="-90 90" damping="50000"/>
                    <geom name="leg2" type="capsule" mass="1.5" fromto="0 0 0 0 0 -28" size="2" rgba=".8 .1 .1 1"/>
                    <geom name="foot" type="capsule" mass="1" fromto="0 0 -28 0 -3 -35" size="1.5"/>
                    <site name="m2_pickup" pos="0 0 -18" size="2" rgba=".1 .1 .8 0.5"/>
                    <site name="knee_pickup" pos="0 0 -28" size="2" rgba=".1 .1 .8 0.5"/>
                    <site name="ankle_start" pos="0 0 -10" size="2" rgba=".1 .1 .8 0.5"/>
                </body>
            </body>

            <site name="x1" pos="13.6 -20.0 0.00" size="2" rgba=".1 .1 .8 0.2"/>
            <body name="servo2" pos="13.6 -5.5 4.3">
                <geom name="motor2" type="cylinder" mass="2" fromto="-3 0 0 3 0 0" size="8" rgba=".8 .1 .1 1" />
                <joint name="m2" pos="0 0 0" type="hinge" axis="1 0 0" limited="true" range="-180 180" damping="50000"/>
                
                <site name="s1" pos="0 0 9" size="2" rgba=".1 .1 .8 0.5"/>
            </body>
        </body>
    </worldbody>


    <contact>
        <exclude body1="main_leg" body2="servo2"/>
    </contact>

    
    <tendon>
        <spatial name="m2_tendon" limited="true" range="0 58.7" width="1" rgba=".1 .1 .8 0.5">
            <site site="s1"/>
            <geom geom="motor2" sidesite="x1"/>
            <site site="m2_pickup"/>
        </spatial>

        <!-- adjust the stiffness values of these springs -->
        <spatial name="knee_tendon" springlength="44" stiffness="80000" width="1" rgba=".1 .1 .8 0.5">
            <site site="knee_start"/>
            <site site="knee_pickup"/>
        </spatial>

        <!--spatial name="ankle_tendon" springlength="0.013" stiffness="2000" width="0.001" rgba=".1 .1 .8 0.5">
            <site site="ankle_start"/>
            <site site="ankle_pickup"/>
        </spatial-->
    </tendon>

    <sensor>
        <!-- tendonpos name="tendon_length" tendon="m2_tendon"/-->
        <!-- framepos name="leg_endpoint" objtype="site" objname="end_point"/-->
        <jointpos name="m1" joint="m1"/>
        <jointpos name="m2" joint="m2"/>
        <actuatorfrc name="m1_f" actuator="m1"/>
        <actuatorfrc name="m2_f" actuator="m2"/>
    </sensor>

    <actuator>
        <position name="m1" gear="1" ctrllimited="true" ctrlrange="-3.00 3.00" joint="m1" kp="10000000"/>
        <position name="m2" gear="1" ctrllimited="true"  ctrlrange="-3.00 3.00 " joint="m2" kp="10000000"/>
        <!--motor name="m1" gear="100" joint="m1"/>
        <motor name="m2" gear="10" joint="m2"/-->
    </actuator>
</mujoco>