<mujoco>
    <body name="tail">
        <geom name="tail_main" type="box" mass="0.009" euler="-19 0 0" size="0.007 0.0175 0.01" pos="0 0.0175 -0.013" rgba=".7 .7 .7 1"/>
        <site name="st_1" pos="0.007 0.022 -0.01" size="0.001" rgba="1 .4 .4 0.3"/>
        <site name="st_2" pos="-0.007 0.022 -0.01" size="0.001" rgba="1 .4 .4 0.3"/>
        <site name="st_3" pos="0.0055 0.0332 -0.0168" size="0.001" rgba="1 .4 .4 0.3"/>
        <site name="st_4" pos="-0.0055 0.0332 -0.0168" size="0.001" rgba="1 .4 .4 0.3"/>

        <body name="tail_t1" pos="0 0.03525 -0.0174">
            <geom name="tail_t1" type="capsule" mass="0.0005" fromto="0 0 0.001 0 0.008 -0.00175" size="0.0055" rgba=".5 .5 .5 1"/>
            <joint name="tail_t1" type="hinge" axis="0 0 1" damping="0.01" stiffness="1.2" armature="0.00065" limited="true" range="-90 90" ref="0"/>
            <site name="st_5" pos="0.0055 0.00175 -0.0006" size="0.001" rgba="1 .4 .4 0.3"/>
            <site name="st_6" pos="-0.0055 0.00175 -0.0006" size="0.001" rgba="1 .4 .4 0.3"/>
            <site name="st_7" pos="0.0055 0.00625 -0.0021" size="0.001" rgba="1 .4 .4 0.3"/>
            <site name="st_8" pos="-0.0055 0.00625 -0.0021" size="0.001" rgba="1 .4 .4 0.3"/>

            <body name="tail_t2" pos="0 0.008 -0.00275">
                <geom name="tail_t2" type="capsule" mass="0.0005" fromto="0 0 0.001 0 0.008 -0.00155" size="0.0054" rgba=".5 .5 .5 1"/>
                <joint name="tail_t2" type="hinge" axis="0 0 1" damping="0.01" stiffness="1.2" armature="0.00065" limited="true" range="-90 90" ref="0"/>
                <site name="st_9" pos="0.00545 0.00175 -0.00055" size="0.001" rgba="1 .4 .4 0.3"/>
                <site name="st_10" pos="-0.00545 0.00175 -0.00055" size="0.001" rgba="1 .4 .4 0.3"/>
                <site name="st_11" pos="0.00545 0.00625 -0.00199" size="0.001" rgba="1 .4 .4 0.3"/>
                <site name="st_12" pos="-0.00545 0.00625 -0.00199" size="0.001" rgba="1 .4 .4 0.3"/>

                <body name="tail_t3" pos="0 0.008 -0.00255">
                    <geom name="tail_t3" type="capsule" mass="0.0005" fromto="0 0 0.001 0 0.008 -0.00145" size="0.0053" rgba=".5 .5 .5 1"/>
                    <joint name="tail_t3" type="hinge" axis="0 0 1" damping="0.01" stiffness="1.2" armature="0.00065" limited="true" range="-90 90" ref="0"/>
                    <site name="st_13" pos="0.0052 0.00175 -0.00053" size="0.001" rgba="1 .4 .4 0.3"/>
                    <site name="st_14" pos="-0.0052 0.00175 -0.00053" size="0.001" rgba="1 .4 .4 0.3"/>
                    <site name="st_15" pos="0.0052 0.00625 -0.00191" size="0.001" rgba="1 .4 .4 0.3"/>
                    <site name="st_16" pos="-0.0052 0.00625 -0.00191" size="0.001" rgba="1 .4 .4 0.3"/>

                    <body name="tail_t4" pos="0 0.008 -0.00245">
                        <geom name="tail_t4" type="capsule" mass="0.0005" fromto="0 0 0.001 0 0.008 -0.00125" size="0.0052" rgba=".5 .5 .5 1"/>
                        <joint name="tail_t4" type="hinge" axis="0 0 1" damping="0.01" stiffness="1.2" armature="0.00065" limited="true" range="-90 90" ref="0"/>
                        <site name="st_17" pos="0.00505 0.00175 -0.00049" size="0.001" rgba="1 .4 .4 0.3"/>
                        <site name="st_18" pos="-0.00505 0.00175 -0.00049" size="0.001" rgba="1 .4 .4 0.3"/>
                        <site name="st_19" pos="0.00505 0.00625 -0.00175" size="0.001" rgba="1 .4 .4 0.3"/>
                        <site name="st_20" pos="-0.00505 0.00625 -0.00175" size="0.001" rgba="1 .4 .4 0.3"/>

                        <body name="tail_t5" pos="0 0.008 -0.00225">
                            <geom name="tail_t5" type="capsule" mass="0.0005" fromto="0 0 0.001 0 0.008 -0.0011" size="0.0051" rgba=".5 .5 .5 1"/>
                            <joint name="tail_t5" type="hinge" axis="0 0 1" damping="0.01" stiffness="1.2" armature="0.00065" limited="true" range="-90 90" ref="0"/>
                            <site name="st_21" pos="0.00495 0.00175 -0.00046" size="0.001" rgba="1 .4 .4 0.3"/>
                            <site name="st_22" pos="-0.00495 0.00175 -0.00046" size="0.001" rgba="1 .4 .4 0.3"/>
                            <site name="st_23" pos="0.00495 0.00625 -0.00164" size="0.001" rgba="1 .4 .4 0.3"/>
                            <site name="st_24" pos="-0.00495 0.00625 -0.00164" size="0.001" rgba="1 .4 .4 0.3"/>

                            <body name="tail_t6" pos="0 0.008 -0.0021">
                                <geom name="tail_t6" type="capsule" mass="0.0005" fromto="0 0 0.001 0 0.008 -0.00095" size="0.005" rgba=".5 .5 .5 1"/>
                                <joint name="tail_t6" type="hinge" axis="0 0 1" damping="0.01" stiffness="1.2" armature="0.00065" limited="true" range="-90 90" ref="0"/>
                                <site name="st_25" pos="0.0049 0.00175 -0.00043" size="0.001" rgba="1 .4 .4 0.3"/>
                                <site name="st_26" pos="-0.0049 0.00175 -0.00043" size="0.001" rgba="1 .4 .4 0.3"/>
                                <site name="st_27" pos="0.0049 0.00625 -0.00152" size="0.001" rgba="1 .4 .4 0.3"/>
                                <site name="st_28" pos="-0.0049 0.00625 -0.00152" size="0.001" rgba="1 .4 .4 0.3"/>

                                <body name="tail_t7" pos="0 0.008 -0.00195">
                                    <geom name="tail_t7" type="capsule" mass="0.0005" fromto="0 0 0.001 0 0.008 -0.0008" size="0.0049" rgba=".5 .5 .5 1"/>
                                    <joint name="tail_t7" type="hinge" axis="0 0 1" damping="0.01" stiffness="1.2" armature="0.00065" limited="true" range="-90 90" ref="0"/>
                                    <site name="st_29" pos="0.0048 0.00175 -0.00039" size="0.001" rgba="1 .4 .4 0.3"/>
                                    <site name="st_30" pos="-0.0048 0.00175 -0.00039" size="0.001" rgba="1 .4 .4 0.3"/>
                                    <site name="st_31" pos="0.0048 0.00625 -0.00141" size="0.001" rgba="1 .4 .4 0.3"/>
                                    <site name="st_32" pos="-0.0048 0.00625 -0.00141" size="0.001" rgba="1 .4 .4 0.3"/>

                                    <body name="tail_t8" pos="0 0.008 -0.0018">
                                        <geom name="tail_t8" type="capsule" mass="0.0005" fromto="0 0 0.001 0 0.008 -0.00065" size="0.0048" rgba=".5 .5 .5 1"/>
                                        <joint name="tail_t8" type="hinge" axis="0 0 1" damping="0.01" stiffness="1.2" armature="0.00065" limited="true" range="-90 90" ref="0"/>
                                        <site name="st_33" pos="0.0046 0.00175 -0.00036" size="0.001" rgba="1 .4 .4 0.3"/>
                                        <site name="st_34" pos="-0.0046 0.00175 -0.00036" size="0.001" rgba="1 .4 .4 0.3"/>
                                        <site name="st_35" pos="0.0046 0.00625 -0.00129" size="0.001" rgba="1 .4 .4 0.3"/>
                                        <site name="st_36" pos="-0.0046 0.00625 -0.00129" size="0.001" rgba="1 .4 .4 0.3"/>

                                        <body name="tail_t9" pos="0 0.008 -0.00165">
                                            <geom name="tail_t9" type="capsule" mass="0.0005" fromto="0 0 0.001 0 0.008 -0.0005" size="0.0047" rgba=".5 .5 .5 1"/>
                                            <joint name="tail_t9" type="hinge" axis="0 0 1" damping="0.01" stiffness="1.2" armature="0.00065" limited="true" range="-90 90" ref="0"/>
                                            <site name="st_37" pos="0.0044 0.00175 -0.00033" size="0.001" rgba="1 .4 .4 0.3"/>
                                            <site name="st_38" pos="-0.0044 0.00175 -0.00033" size="0.001" rgba="1 .4 .4 0.3"/>
                                            <site name="st_39" pos="0.0044 0.00625 -0.00117" size="0.001" rgba="1 .4 .4 0.3"/>
                                            <site name="st_40" pos="-0.0044 0.00625 -0.00117" size="0.001" rgba="1 .4 .4 0.3"/>

                                            <body name="tail_t10" pos="0 0.008 -0.0015">
                                                <geom name="tail_t10" type="capsule" mass="0.0005" fromto="0 0 0.001 0 0.008 -0.00035" size="0.0046" rgba=".5 .5 .5 1"/>
                                                <joint name="tail_t10" type="hinge" axis="0 0 1" damping="0.01" stiffness="1.2" armature="0.00065" limited="true" range="-90 90" ref="0"/>
                                                <site name="st_41" pos="0.0042 0.00175 -0.000295" size="0.001" rgba="1 .4 .4 0.3"/>
                                                <site name="st_42" pos="-0.0042 0.00175 -0.000295" size="0.001" rgba="1 .4 .4 0.3"/>
                                                <site name="st_43" pos="0.0042 0.00625 -0.00105" size="0.001" rgba="1 .4 .4 0.3"/>
                                                <site name="st_44" pos="-0.0042 0.00625 -0.00105" size="0.001" rgba="1 .4 .4 0.3"/>

                                                <body name="tail_t11" pos="0 0.008 -0.00135">
                                                    <geom name="tail_t11" type="capsule" mass="0.0005" fromto="0 0 0.001 0 0.008 -0.0002" size="0.0045" rgba=".5 .5 .5 1"/>
                                                    <joint name="tail_t11" type="hinge" axis="0 0 1" damping="0.01" stiffness="1.2" armature="0.00065" limited="true" range="-90 90" ref="0"/>
                                                    <site name="st_45" pos="0.00405 0.00175 -0.00026" size="0.001" rgba="1 .4 .4 0.3"/>
                                                    <site name="st_46" pos="-0.00405 0.00175 -0.00026" size="0.001" rgba="1 .4 .4 0.3"/>
                                                    <site name="st_47" pos="0.00405 0.00625 -0.00094" size="0.001" rgba="1 .4 .4 0.3"/>
                                                    <site name="st_48" pos="-0.00405 0.00625 -0.00094" size="0.001" rgba="1 .4 .4 0.3"/>

                                                    <body name="tail_t12" pos="0 0.008 -0.0012">
                                                        <geom name="tail_t12" type="capsule" mass="0.0005" fromto="0 0 0.001 0 0.008 -0.00005" size="0.0044" rgba=".5 .5 .5 1"/>
                                                        <joint name="tail_t12" type="hinge" axis="0 0 1" damping="0.01" stiffness="1.2" armature="0.00065" limited="true" range="-90 90" ref="0"/>
                                                        <site name="st_49" pos="0.0040 0.00175 -0.00023" size="0.001" rgba="1 .4 .4 0.3"/>
                                                        <site name="st_50" pos="-0.0040 0.00175 -0.00023" size="0.001" rgba="1 .4 .4 0.3"/>
                                                        <site name="st_51" pos="0.0040 0.00625 -0.00082" size="0.001" rgba="1 .4 .4 0.3"/>
                                                        <site name="st_52" pos="-0.0040 0.00625 -0.00082" size="0.001" rgba="1 .4 .4 0.3"/>

                                                        <body name="tail_t13" pos="0 0.008 -0.00105">
                                                            <geom name="tail_t13" type="capsule" mass="0.0005" fromto="0 0 0.001 0 0.008 0.0001" size="0.0043" rgba=".5 .5 .5 1"/>
                                                            <joint name="tail_t13" type="hinge" axis="0 0 1" damping="0.01" stiffness="1.2" armature="0.00065" limited="true" range="-90 90" ref="0"/>
                                                            <site name="st_53" pos="0.0039 0.00175 -0.000196" size="0.001" rgba="1 .4 .4 0.3"/>
                                                            <site name="st_54" pos="-0.0039 0.00175 -0.000196" size="0.001" rgba="1 .4 .4 0.3"/>
                                                            <site name="st_55" pos="0.0039 0.00625 -0.00070" size="0.001" rgba="1 .4 .4 0.3"/>
                                                            <site name="st_56" pos="-0.0039 0.00625 -0.00070" size="0.001" rgba="1 .4 .4 0.3"/>

                                                            <body name="tail_t14" pos="0 0.008 -0.0009">
                                                                <geom name="tail_t14" type="capsule" mass="0.0005" fromto="0 0 0.001 0 0.008 0.00025" size="0.0042" rgba=".5 .5 .5 1"/>
                                                                <joint name="tail_t14" type="hinge" axis="0 0 1" damping="0.01" stiffness="1.2" armature="0.00065" limited="true" range="-90 90" ref="0"/>
                                                                <site name="st_57" pos="0.00375 0.00175 -0.000164" size="0.001" rgba="1 .4 .4 0.3"/>
                                                                <site name="st_58" pos="-0.00375 0.00175 -0.000164" size="0.001" rgba="1 .4 .4 0.3"/>
                                                                <site name="st_59" pos="0.00375 0.00625 -0.000585" size="0.001" rgba="1 .4 .4 0.3"/>
                                                                <site name="st_60" pos="-0.00375 0.00625 -0.000585" size="0.001" rgba="1 .4 .4 0.3"/>

                                                                <body name="tail_t15" pos="0 0.008 -0.00075">
                                                                    <geom name="tail_t15" type="capsule" mass="0.0005" fromto="0 0 0.001 0 0.008 0.0004" size="0.0041" rgba=".5 .5 .5 1"/>
                                                                    <joint name="tail_t15" type="hinge" axis="0 0 1" damping="0.01" stiffness="1.2" armature="0.00065" limited="true" range="-90 90" ref="0"/>
                                                                    <site name="st_61" pos="0.0036 0.00175 -0.00013" size="0.001" rgba="1 .4 .4 0.3"/>
                                                                    <site name="st_62" pos="-0.0036 0.00175 -0.00013" size="0.001" rgba="1 .4 .4 0.3"/>
                                                                    <site name="st_63" pos="0.0036 0.00625 -0.00047" size="0.001" rgba="1 .4 .4 0.3"/>
                                                                    <site name="st_64" pos="-0.0036 0.00625 -0.00047" size="0.001" rgba="1 .4 .4 0.3"/>

                                                                    <body name="tail_t16" pos="0 0.008 -0.0006">
                                                                        <geom name="tail_t16" type="capsule" mass="0.0005" fromto="0 0 0.001 0 0.008 0.00055" size="0.004" rgba=".5 .5 .5 1"/>
                                                                        <joint name="tail_t16" type="hinge" axis="0 0 1" damping="0.01" stiffness="1.2" armature="0.00065" limited="true" range="-90 90" ref="0"/>
                                                                        <site name="st_65" pos="0.0035 0.00175 -0.0001" size="0.001" rgba="1 .4 .4 0.3"/>
                                                                        <site name="st_66" pos="-0.0035 0.00175 -0.0001" size="0.001" rgba="1 .4 .4 0.3"/>
                                                                        <site name="st_67" pos="0.0035 0.00625 -0.00035" size="0.001" rgba="1 .4 .4 0.3"/>
                                                                        <site name="st_68" pos="-0.0035 0.00625 -0.00035" size="0.001" rgba="1 .4 .4 0.3"/>

                                                                        <body name="tail_t17" pos="0 0.008 -0.00045">
                                                                            <geom name="tail_t17" type="capsule" mass="0.0005" fromto="0 0 0.001 0 0.008 0.0007" size="0.0039" rgba=".5 .5 .5 1"/>
                                                                            <joint name="tail_t17" type="hinge" axis="0 0 1" damping="0.01" stiffness="1.2" armature="0.00065" limited="true" range="-90 90" ref="0"/>
                                                                            <site name="st_69" pos="0.00335 0.00175 -0.000065" size="0.001" rgba="1 .4 .4 0.3"/>
                                                                            <site name="st_70" pos="-0.00335 0.00175 -0.000065" size="0.001" rgba="1 .4 .4 0.3"/>
                                                                            <site name="st_71" pos="0.00335 0.00625 -0.00023" size="0.001" rgba="1 .4 .4 0.3"/>
                                                                            <site name="st_72" pos="-0.00335 0.00625 -0.00023" size="0.001" rgba="1 .4 .4 0.3"/>

                                                                            <body name="tail_t18" pos="0 0.008 -0.0003">
                                                                                <geom name="tail_t18" type="capsule" mass="0.0005" fromto="0 0 0.001 0 0.008 0.00085" size="0.0038" rgba=".5 .5 .5 1"/>
                                                                                <joint name="tail_t18" type="hinge" axis="0 0 1" damping="0.01" stiffness="1.2" armature="0.00065" limited="true" range="-90 90" ref="0"/>
                                                                                <site name="st_73" pos="0.0031 0.00175 -0.000032" size="0.001" rgba="1 .4 .4 0.3"/>
                                                                                <site name="st_74" pos="-0.0031 0.00175 -0.000032" size="0.001" rgba="1 .4 .4 0.3"/>
                                                                                <site name="st_75" pos="0.0031 0.00625 -0.00012" size="0.001" rgba="1 .4 .4 0.3"/>
                                                                                <site name="st_76" pos="-0.0031 0.00625 -0.00012" size="0.001" rgba="1 .4 .4 0.3"/>

                                                                                <body name="tail_t19" pos="0 0.008 -0.0003">
                                                                                    <geom name="tail_t19" type="capsule" mass="0.0005" fromto="0 0 0.001 0 0.00525 0.001" size="0.0037" rgba=".5 .5 .5 1"/>
                                                                                    <joint name="tail_t19" type="hinge" axis="0 0 1" damping="0.01" stiffness="1.2" armature="0.00065" limited="true" range="-90 90" ref="0"/>
                                                                                    <site name="st_77" pos="0.003 0.00175 0" size="0.001" rgba="1 .4 .4 0.3"/>
                                                                                    <site name="st_78" pos="-0.003 0.00175 0" size="0.001" rgba="1 .4 .4 0.3"/>
                                                                                    <site name="st_79" pos="0.003 0.00825 0" size="0.001" rgba="1 .4 .4 0.3"/>
                                                                                    <site name="st_80" pos="-0.003 0.00825 0" size="0.001" rgba="1 .4 .4 0.3"/>
                                                                                </body>
                                                                            </body>
                                                                        </body>
                                                                    </body>
                                                                </body>
                                                            </body>
                                                        </body>
                                                    </body>
                                                </body>
                                            </body>
                                        </body>
                                    </body>
                                </body>
                            </body>
                        </body>
                    </body>
                </body>
            </body>
        </body>

        <body name="servo_tail" pos="0 0.0152 0.001" euler="-19 0 0">
                <geom name="m1_tail" type="cylinder" mass="0.001" fromto="0 0 .002 0 0 0.005" size="0.0025" rgba="1 .4 .4 1" />
                <geom name="m1_tail1" type="capsule" mass="0.001" fromto="0.012 0 0.0035 -0.012 0 0.0035" size="0.0015" rgba="1 .4 .4 1"/>
                <joint name="m1_tail" pos="0 0 0" type="hinge" axis="0 0 1" armature="0.00065" damping="0.01" limited="true" range="-180 180" ref="0"/>
                <site name="servo_tail_1" pos="0.008 0 0.0035" size="0.002" rgba="1 .4 .4 0.5"/>
                <site name="servo_tail_2" pos="-0.008 0 0.0035" size="0.002" rgba="1 .4 .4 0.5"/>
        </body>
    </body>
</mujoco>